submitit ERROR (2025-09-04 17:46:18,002) - Submitted job triggered an exception
Traceback (most recent call last):
  File "<frozen runpy>", line 198, in _run_module_as_main
  File "<frozen runpy>", line 88, in _run_code
  File "/home/stefaccou/.pyenv/versions/master_thesis_adapters/lib/python3.12/site-packages/submitit/core/_submit.py", line 11, in <module>
    submitit_main()
  File "/home/stefaccou/.pyenv/versions/master_thesis_adapters/lib/python3.12/site-packages/submitit/core/submission.py", line 76, in submitit_main
    process_job(args.folder)
  File "/home/stefaccou/.pyenv/versions/master_thesis_adapters/lib/python3.12/site-packages/submitit/core/submission.py", line 69, in process_job
    raise error
  File "/home/stefaccou/.pyenv/versions/master_thesis_adapters/lib/python3.12/site-packages/submitit/core/submission.py", line 55, in process_job
    result = delayed.result()
             ^^^^^^^^^^^^^^^^
  File "/home/stefaccou/.pyenv/versions/master_thesis_adapters/lib/python3.12/site-packages/submitit/core/utils.py", line 137, in result
    self._result = self.function(*self.args, **self.kwargs)
                   ^^^^^^^^^^^^^^^^^^^^^^^^^^^^^^^^^^^^^^^^
  File "/mnt/c/Users/stefa/Courses/Master_thesis/gemma_mlm.py", line 36, in main
    import datasets
ModuleNotFoundError: No module named 'datasets'
